Wed 18:34:11 ERROR [Thread-3] sia.ui.SIA - Retrieving contacts and conversations failed.
null
Traceback (most recent call last):
  File "__pyclasspath__/sia/py/fileparsers/GtalkParser.py", line 48, in getContacts
Exception: NO

	at org.python.core.PyException.fillInStackTrace(PyException.java:70)
	at java.lang.Throwable.<init>(Throwable.java:181)
	at java.lang.Exception.<init>(Exception.java:29)
	at java.lang.RuntimeException.<init>(RuntimeException.java:32)
	at org.python.core.PyException.<init>(PyException.java:46)
	at org.python.core.PyException.doRaise(PyException.java:219)
	at org.python.core.Py.makeException(Py.java:1225)
	at org.python.core.Py.makeException(Py.java:1229)
	at org.python.core.Py.makeException(Py.java:1233)
	at sia.py.fileparsers.GtalkParser$py.getContacts$5(__pyclasspath__/sia/py/fileparsers/GtalkParser.py:138)
	at sia.py.fileparsers.GtalkParser$py.call_function(__pyclasspath__/sia/py/fileparsers/GtalkParser.py)
	at org.python.core.PyTableCode.call(PyTableCode.java:165)
	at org.python.core.PyBaseCode.call(PyBaseCode.java:301)
	at org.python.core.PyBaseCode.call(PyBaseCode.java:194)
	at org.python.core.PyFunction.__call__(PyFunction.java:387)
	at org.python.core.PyMethod.instancemethod___call__(PyMethod.java:220)
	at org.python.core.PyMethod.__call__(PyMethod.java:211)
	at org.python.core.PyMethod.__call__(PyMethod.java:201)
	at org.python.core.PyMethod.__call__(PyMethod.java:196)
	at org.python.core.PyObject._jcallexc(PyObject.java:3502)
	at org.python.proxies.sia.py.fileparsers.GtalkParser$GtalkParser$1.getContacts(Unknown Source)
	at sia.datasources.DataSource.getContacts(DataSource.java:132)
	at sia.ui.importui.ImportWizard$2.run(ImportWizard.java:295)
	at java.lang.Thread.run(Thread.java:662)
Wed 18:37:10 ERROR [Thread-3] sia.ui.SIA - Retrieving contacts and conversations failed.
Traceback (most recent call last):
  File "__pyclasspath__/sia/py/fileparsers/GtalkParser.py", line 48, in getContacts
Exception: NO

	at org.python.core.PyException.fillInStackTrace(PyException.java:70)
	at java.lang.Throwable.<init>(Throwable.java:181)
	at java.lang.Exception.<init>(Exception.java:29)
	at java.lang.RuntimeException.<init>(RuntimeException.java:32)
	at org.python.core.PyException.<init>(PyException.java:46)
	at org.python.core.PyException.doRaise(PyException.java:219)
	at org.python.core.Py.makeException(Py.java:1225)
	at org.python.core.Py.makeException(Py.java:1229)
	at org.python.core.Py.makeException(Py.java:1233)
	at sia.py.fileparsers.GtalkParser$py.getContacts$5(__pyclasspath__/sia/py/fileparsers/GtalkParser.py:138)
	at sia.py.fileparsers.GtalkParser$py.call_function(__pyclasspath__/sia/py/fileparsers/GtalkParser.py)
	at org.python.core.PyTableCode.call(PyTableCode.java:165)
	at org.python.core.PyBaseCode.call(PyBaseCode.java:301)
	at org.python.core.PyBaseCode.call(PyBaseCode.java:194)
	at org.python.core.PyFunction.__call__(PyFunction.java:387)
	at org.python.core.PyMethod.instancemethod___call__(PyMethod.java:220)
	at org.python.core.PyMethod.__call__(PyMethod.java:211)
	at org.python.core.PyMethod.__call__(PyMethod.java:201)
	at org.python.core.PyMethod.__call__(PyMethod.java:196)
	at org.python.core.PyObject._jcallexc(PyObject.java:3502)
	at org.python.proxies.sia.py.fileparsers.GtalkParser$GtalkParser$1.getContacts(Unknown Source)
	at sia.datasources.DataSource.getContacts(DataSource.java:132)
	at sia.ui.importui.ImportWizard$2.run(ImportWizard.java:295)
	at java.lang.Thread.run(Thread.java:662)
Wed 18:44:35 ERROR [Thread-5] sia.ui.SIA - Retrieving contacts and conversations failed.
Traceback (most recent call last):
  File "__pyclasspath__/sia/py/fileparsers/GtalkParser.py", line 45, in getContacts
  File "/opt/jython2.5.2/Lib/imaplib.py", line 501, in login
    raise self.error(dat[-1])
imaplib.error: [AUTHENTICATIONFAILED] Invalid credentials (Failure)

	at org.python.core.PyException.fillInStackTrace(PyException.java:70)
	at java.lang.Throwable.<init>(Throwable.java:181)
	at java.lang.Exception.<init>(Exception.java:29)
	at java.lang.RuntimeException.<init>(RuntimeException.java:32)
	at org.python.core.PyException.<init>(PyException.java:46)
	at org.python.core.PyException.doRaise(PyException.java:219)
	at org.python.core.Py.makeException(Py.java:1225)
	at org.python.core.Py.makeException(Py.java:1229)
	at org.python.core.Py.makeException(Py.java:1233)
	at imaplib$py.login$31(/opt/jython2.5.2/Lib/imaplib.py:503)
	at imaplib$py.call_function(/opt/jython2.5.2/Lib/imaplib.py)
	at org.python.core.PyTableCode.call(PyTableCode.java:165)
	at org.python.core.PyBaseCode.call(PyBaseCode.java:166)
	at org.python.core.PyFunction.__call__(PyFunction.java:338)
	at org.python.core.PyMethod.__call__(PyMethod.java:139)
	at sia.py.fileparsers.GtalkParser$py.getContacts$5(__pyclasspath__/sia/py/fileparsers/GtalkParser.py:136)
	at sia.py.fileparsers.GtalkParser$py.call_function(__pyclasspath__/sia/py/fileparsers/GtalkParser.py)
	at org.python.core.PyTableCode.call(PyTableCode.java:165)
	at org.python.core.PyBaseCode.call(PyBaseCode.java:301)
	at org.python.core.PyBaseCode.call(PyBaseCode.java:194)
	at org.python.core.PyFunction.__call__(PyFunction.java:387)
	at org.python.core.PyMethod.instancemethod___call__(PyMethod.java:220)
	at org.python.core.PyMethod.__call__(PyMethod.java:211)
	at org.python.core.PyMethod.__call__(PyMethod.java:201)
	at org.python.core.PyMethod.__call__(PyMethod.java:196)
	at org.python.core.PyObject._jcallexc(PyObject.java:3502)
	at org.python.proxies.sia.py.fileparsers.GtalkParser$GtalkParser$1.getContacts(Unknown Source)
	at sia.datasources.DataSource.getContacts(DataSource.java:132)
	at sia.ui.importui.ImportWizard$2.run(ImportWizard.java:295)
	at java.lang.Thread.run(Thread.java:662)
Wed 18:47:16 ERROR [Thread-3] sia.ui.SIA - Retrieving contacts and conversations failed.
Traceback (most recent call last):
  File "__pyclasspath__/sia/py/fileparsers/GtalkParser.py", line 45, in getContacts
  File "/opt/jython2.5.2/Lib/imaplib.py", line 501, in login
    raise self.error(dat[-1])
imaplib.error: [AUTHENTICATIONFAILED] Invalid credentials (Failure)

	at org.python.core.PyException.fillInStackTrace(PyException.java:70)
	at java.lang.Throwable.<init>(Throwable.java:181)
	at java.lang.Exception.<init>(Exception.java:29)
	at java.lang.RuntimeException.<init>(RuntimeException.java:32)
	at org.python.core.PyException.<init>(PyException.java:46)
	at org.python.core.PyException.doRaise(PyException.java:219)
	at org.python.core.Py.makeException(Py.java:1225)
	at org.python.core.Py.makeException(Py.java:1229)
	at org.python.core.Py.makeException(Py.java:1233)
	at imaplib$py.login$31(/opt/jython2.5.2/Lib/imaplib.py:503)
	at imaplib$py.call_function(/opt/jython2.5.2/Lib/imaplib.py)
	at org.python.core.PyTableCode.call(PyTableCode.java:165)
	at org.python.core.PyBaseCode.call(PyBaseCode.java:166)
	at org.python.core.PyFunction.__call__(PyFunction.java:338)
	at org.python.core.PyMethod.__call__(PyMethod.java:139)
	at sia.py.fileparsers.GtalkParser$py.getContacts$5(__pyclasspath__/sia/py/fileparsers/GtalkParser.py:144)
	at sia.py.fileparsers.GtalkParser$py.call_function(__pyclasspath__/sia/py/fileparsers/GtalkParser.py)
	at org.python.core.PyTableCode.call(PyTableCode.java:165)
	at org.python.core.PyBaseCode.call(PyBaseCode.java:301)
	at org.python.core.PyBaseCode.call(PyBaseCode.java:194)
	at org.python.core.PyFunction.__call__(PyFunction.java:387)
	at org.python.core.PyMethod.instancemethod___call__(PyMethod.java:220)
	at org.python.core.PyMethod.__call__(PyMethod.java:211)
	at org.python.core.PyMethod.__call__(PyMethod.java:201)
	at org.python.core.PyMethod.__call__(PyMethod.java:196)
	at org.python.core.PyObject._jcallexc(PyObject.java:3502)
	at org.python.proxies.sia.py.fileparsers.GtalkParser$GtalkParser$1.getContacts(Unknown Source)
	at sia.datasources.DataSource.getContacts(DataSource.java:132)
	at sia.ui.importui.ImportWizard$2.run(ImportWizard.java:295)
	at java.lang.Thread.run(Thread.java:662)
Wed 18:55:58 ERROR [main] sia.ui.SIA - Data source handler not found.
Traceback (most recent call last):
  File "<string>", line 1, in <module>
SyntaxError: ("mismatched input 'as' expecting COLON", ('__pyclasspath__/sia/py/fileparsers/GtalkParser.py', 47, 19, '\t\texcept Exception as e:\n'))

	at org.python.core.PyException.fillInStackTrace(PyException.java:70)
	at java.lang.Throwable.<init>(Throwable.java:181)
	at java.lang.Exception.<init>(Exception.java:29)
	at java.lang.RuntimeException.<init>(RuntimeException.java:32)
	at org.python.core.PyException.<init>(PyException.java:46)
	at org.python.core.PyException.<init>(PyException.java:43)
	at org.python.core.PyException.<init>(PyException.java:39)
	at org.python.core.PySyntaxError.<init>(PySyntaxError.java:22)
	at org.python.core.ParserFacade.fixParseError(ParserFacade.java:92)
	at org.python.core.ParserFacade.parse(ParserFacade.java:186)
	at org.python.core.imp.compileSource(imp.java:321)
	at org.python.core.imp.compileSource(imp.java:310)
	at org.python.core.util.importer.getModuleCode(importer.java:211)
	at org.python.core.util.importer.importer_load_module(importer.java:95)
	at org.python.core.ClasspathPyImporter.ClasspathPyImporter_load_module(ClasspathPyImporter.java:63)
	at org.python.core.ClasspathPyImporter$ClasspathPyImporter_load_module_exposer.__call__(Unknown Source)
	at org.python.core.PyBuiltinMethodNarrow.__call__(PyBuiltinMethodNarrow.java:47)
	at org.python.core.imp.loadFromLoader(imp.java:513)
	at org.python.core.imp.find_module(imp.java:467)
	at org.python.core.PyModule.impAttr(PyModule.java:100)
	at org.python.core.imp.import_next(imp.java:715)
	at org.python.core.imp.import_logic(imp.java:777)
	at org.python.core.imp.import_name(imp.java:839)
	at org.python.core.imp.importName(imp.java:884)
	at org.python.core.ImportFunction.__call__(__builtin__.java:1220)
	at org.python.core.PyObject.__call__(PyObject.java:357)
	at org.python.core.__builtin__.__import__(__builtin__.java:1173)
	at org.python.core.imp.importFromAs(imp.java:978)
	at org.python.core.imp.importFrom(imp.java:954)
	at org.python.pycode._pyx0.f$0(<string>:1)
	at org.python.pycode._pyx0.call_function(<string>)
	at org.python.core.PyTableCode.call(PyTableCode.java:165)
	at org.python.core.PyCode.call(PyCode.java:18)
	at org.python.core.Py.runCode(Py.java:1261)
	at org.python.core.Py.exec(Py.java:1305)
	at org.python.util.PythonInterpreter.exec(PythonInterpreter.java:206)
	at sia.utils.ParserFactory.<init>(ParserFactory.java:27)
	at sia.datasources.GtalkDataSource.<init>(GtalkDataSource.java:19)
	at sun.reflect.NativeConstructorAccessorImpl.newInstance0(Native Method)
	at sun.reflect.NativeConstructorAccessorImpl.newInstance(NativeConstructorAccessorImpl.java:39)
	at sun.reflect.DelegatingConstructorAccessorImpl.newInstance(DelegatingConstructorAccessorImpl.java:27)
	at java.lang.reflect.Constructor.newInstance(Constructor.java:513)
	at java.lang.Class.newInstance0(Class.java:355)
	at java.lang.Class.newInstance(Class.java:308)
	at sia.utils.Dictionaries.getDataSource(Dictionaries.java:81)
	at sia.ui.importui.ImportWizard.handlePageChanging(ImportWizard.java:206)
	at org.eclipse.jface.wizard.WizardDialog$10.run(WizardDialog.java:1602)
	at org.eclipse.jface.util.SafeRunnable$1.run(SafeRunnable.java:128)
	at org.eclipse.jface.util.SafeRunnable.run(SafeRunnable.java:175)
	at org.eclipse.jface.wizard.WizardDialog.firePageChanging(WizardDialog.java:1600)
	at org.eclipse.jface.wizard.WizardDialog.doPageChanging(WizardDialog.java:929)
	at org.eclipse.jface.wizard.WizardDialog.showPage(WizardDialog.java:1218)
	at org.eclipse.jface.wizard.WizardDialog.nextPressed(WizardDialog.java:915)
	at org.eclipse.jface.wizard.WizardDialog.buttonPressed(WizardDialog.java:428)
	at org.eclipse.jface.dialogs.Dialog$2.widgetSelected(Dialog.java:624)
	at org.eclipse.swt.widgets.TypedListener.handleEvent(TypedListener.java:240)
	at org.eclipse.swt.widgets.EventTable.sendEvent(EventTable.java:84)
	at org.eclipse.swt.widgets.Widget.sendEvent(Widget.java:1258)
	at org.eclipse.swt.widgets.Display.runDeferredEvents(Display.java:3588)
	at org.eclipse.swt.widgets.Display.readAndDispatch(Display.java:3209)
	at org.eclipse.jface.window.Window.runEventLoop(Window.java:825)
	at org.eclipse.jface.window.Window.open(Window.java:801)
	at sia.ui.Start$1.widgetSelected(Start.java:114)
	at org.eclipse.swt.widgets.TypedListener.handleEvent(TypedListener.java:240)
	at org.eclipse.swt.widgets.EventTable.sendEvent(EventTable.java:84)
	at org.eclipse.swt.widgets.Widget.sendEvent(Widget.java:1258)
	at org.eclipse.swt.widgets.Display.runDeferredEvents(Display.java:3588)
	at org.eclipse.swt.widgets.Display.readAndDispatch(Display.java:3209)
	at org.eclipse.jface.window.Window.runEventLoop(Window.java:825)
	at org.eclipse.jface.window.Window.open(Window.java:801)
	at sia.ui.Start.run(Start.java:85)
	at sia.ui.SIA.guiInit(SIA.java:179)
	at sia.ui.SIA.init(SIA.java:46)
	at sia.ui.SIA.main(SIA.java:213)
Wed 18:56:00 ERROR [main] sia.ui.SIA - An unexpected error occured.
java.lang.NullPointerException
	at sia.ui.importui.ImportWizard.handlePageChanging(ImportWizard.java:207)
	at org.eclipse.jface.wizard.WizardDialog$10.run(WizardDialog.java:1602)
	at org.eclipse.jface.util.SafeRunnable$1.run(SafeRunnable.java:128)
	at org.eclipse.jface.util.SafeRunnable.run(SafeRunnable.java:175)
	at org.eclipse.jface.wizard.WizardDialog.firePageChanging(WizardDialog.java:1600)
	at org.eclipse.jface.wizard.WizardDialog.doPageChanging(WizardDialog.java:929)
	at org.eclipse.jface.wizard.WizardDialog.showPage(WizardDialog.java:1218)
	at org.eclipse.jface.wizard.WizardDialog.nextPressed(WizardDialog.java:915)
	at org.eclipse.jface.wizard.WizardDialog.buttonPressed(WizardDialog.java:428)
	at org.eclipse.jface.dialogs.Dialog$2.widgetSelected(Dialog.java:624)
	at org.eclipse.swt.widgets.TypedListener.handleEvent(TypedListener.java:240)
	at org.eclipse.swt.widgets.EventTable.sendEvent(EventTable.java:84)
	at org.eclipse.swt.widgets.Widget.sendEvent(Widget.java:1258)
	at org.eclipse.swt.widgets.Display.runDeferredEvents(Display.java:3588)
	at org.eclipse.swt.widgets.Display.readAndDispatch(Display.java:3209)
	at org.eclipse.jface.window.Window.runEventLoop(Window.java:825)
	at org.eclipse.jface.window.Window.open(Window.java:801)
	at sia.ui.Start$1.widgetSelected(Start.java:114)
	at org.eclipse.swt.widgets.TypedListener.handleEvent(TypedListener.java:240)
	at org.eclipse.swt.widgets.EventTable.sendEvent(EventTable.java:84)
	at org.eclipse.swt.widgets.Widget.sendEvent(Widget.java:1258)
	at org.eclipse.swt.widgets.Display.runDeferredEvents(Display.java:3588)
	at org.eclipse.swt.widgets.Display.readAndDispatch(Display.java:3209)
	at org.eclipse.jface.window.Window.runEventLoop(Window.java:825)
	at org.eclipse.jface.window.Window.open(Window.java:801)
	at sia.ui.Start.run(Start.java:85)
	at sia.ui.SIA.guiInit(SIA.java:179)
	at sia.ui.SIA.init(SIA.java:46)
	at sia.ui.SIA.main(SIA.java:213)
Wed 18:58:56 ERROR [main] sia.ui.SIA - Data source handler not found.
Traceback (most recent call last):
  File "<string>", line 1, in <module>
SyntaxError: ("mismatched input 'as' expecting COLON", ('__pyclasspath__/sia/py/fileparsers/GtalkParser.py', 47, 19, '\t\texcept Exception as e:\n'))

	at org.python.core.PyException.fillInStackTrace(PyException.java:70)
	at java.lang.Throwable.<init>(Throwable.java:181)
	at java.lang.Exception.<init>(Exception.java:29)
	at java.lang.RuntimeException.<init>(RuntimeException.java:32)
	at org.python.core.PyException.<init>(PyException.java:46)
	at org.python.core.PyException.<init>(PyException.java:43)
	at org.python.core.PyException.<init>(PyException.java:39)
	at org.python.core.PySyntaxError.<init>(PySyntaxError.java:22)
	at org.python.core.ParserFacade.fixParseError(ParserFacade.java:92)
	at org.python.core.ParserFacade.parse(ParserFacade.java:186)
	at org.python.core.imp.compileSource(imp.java:321)
	at org.python.core.imp.compileSource(imp.java:310)
	at org.python.core.util.importer.getModuleCode(importer.java:211)
	at org.python.core.util.importer.importer_load_module(importer.java:95)
	at org.python.core.ClasspathPyImporter.ClasspathPyImporter_load_module(ClasspathPyImporter.java:63)
	at org.python.core.ClasspathPyImporter$ClasspathPyImporter_load_module_exposer.__call__(Unknown Source)
	at org.python.core.PyBuiltinMethodNarrow.__call__(PyBuiltinMethodNarrow.java:47)
	at org.python.core.imp.loadFromLoader(imp.java:513)
	at org.python.core.imp.find_module(imp.java:467)
	at org.python.core.PyModule.impAttr(PyModule.java:100)
	at org.python.core.imp.import_next(imp.java:715)
	at org.python.core.imp.import_logic(imp.java:777)
	at org.python.core.imp.import_name(imp.java:839)
	at org.python.core.imp.importName(imp.java:884)
	at org.python.core.ImportFunction.__call__(__builtin__.java:1220)
	at org.python.core.PyObject.__call__(PyObject.java:357)
	at org.python.core.__builtin__.__import__(__builtin__.java:1173)
	at org.python.core.imp.importFromAs(imp.java:978)
	at org.python.core.imp.importFrom(imp.java:954)
	at org.python.pycode._pyx0.f$0(<string>:1)
	at org.python.pycode._pyx0.call_function(<string>)
	at org.python.core.PyTableCode.call(PyTableCode.java:165)
	at org.python.core.PyCode.call(PyCode.java:18)
	at org.python.core.Py.runCode(Py.java:1261)
	at org.python.core.Py.exec(Py.java:1305)
	at org.python.util.PythonInterpreter.exec(PythonInterpreter.java:206)
	at sia.utils.ParserFactory.<init>(ParserFactory.java:27)
	at sia.datasources.GtalkDataSource.<init>(GtalkDataSource.java:19)
	at sun.reflect.NativeConstructorAccessorImpl.newInstance0(Native Method)
	at sun.reflect.NativeConstructorAccessorImpl.newInstance(NativeConstructorAccessorImpl.java:39)
	at sun.reflect.DelegatingConstructorAccessorImpl.newInstance(DelegatingConstructorAccessorImpl.java:27)
	at java.lang.reflect.Constructor.newInstance(Constructor.java:513)
	at java.lang.Class.newInstance0(Class.java:355)
	at java.lang.Class.newInstance(Class.java:308)
	at sia.utils.Dictionaries.getDataSource(Dictionaries.java:81)
	at sia.ui.importui.ImportWizard.handlePageChanging(ImportWizard.java:206)
	at org.eclipse.jface.wizard.WizardDialog$10.run(WizardDialog.java:1602)
	at org.eclipse.jface.util.SafeRunnable$1.run(SafeRunnable.java:128)
	at org.eclipse.jface.util.SafeRunnable.run(SafeRunnable.java:175)
	at org.eclipse.jface.wizard.WizardDialog.firePageChanging(WizardDialog.java:1600)
	at org.eclipse.jface.wizard.WizardDialog.doPageChanging(WizardDialog.java:929)
	at org.eclipse.jface.wizard.WizardDialog.showPage(WizardDialog.java:1218)
	at org.eclipse.jface.wizard.WizardDialog.nextPressed(WizardDialog.java:915)
	at org.eclipse.jface.wizard.WizardDialog.buttonPressed(WizardDialog.java:428)
	at org.eclipse.jface.dialogs.Dialog$2.widgetSelected(Dialog.java:624)
	at org.eclipse.swt.widgets.TypedListener.handleEvent(TypedListener.java:240)
	at org.eclipse.swt.widgets.EventTable.sendEvent(EventTable.java:84)
	at org.eclipse.swt.widgets.Widget.sendEvent(Widget.java:1258)
	at org.eclipse.swt.widgets.Display.runDeferredEvents(Display.java:3588)
	at org.eclipse.swt.widgets.Display.readAndDispatch(Display.java:3209)
	at org.eclipse.jface.window.Window.runEventLoop(Window.java:825)
	at org.eclipse.jface.window.Window.open(Window.java:801)
	at sia.ui.Start$1.widgetSelected(Start.java:114)
	at org.eclipse.swt.widgets.TypedListener.handleEvent(TypedListener.java:240)
	at org.eclipse.swt.widgets.EventTable.sendEvent(EventTable.java:84)
	at org.eclipse.swt.widgets.Widget.sendEvent(Widget.java:1258)
	at org.eclipse.swt.widgets.Display.runDeferredEvents(Display.java:3588)
	at org.eclipse.swt.widgets.Display.readAndDispatch(Display.java:3209)
	at org.eclipse.jface.window.Window.runEventLoop(Window.java:825)
	at org.eclipse.jface.window.Window.open(Window.java:801)
	at sia.ui.Start.run(Start.java:85)
	at sia.ui.SIA.guiInit(SIA.java:179)
	at sia.ui.SIA.init(SIA.java:46)
	at sia.ui.SIA.main(SIA.java:213)
Wed 18:58:57 ERROR [main] sia.ui.SIA - An unexpected error occured.
java.lang.NullPointerException
	at sia.ui.importui.ImportWizard.handlePageChanging(ImportWizard.java:207)
	at org.eclipse.jface.wizard.WizardDialog$10.run(WizardDialog.java:1602)
	at org.eclipse.jface.util.SafeRunnable$1.run(SafeRunnable.java:128)
	at org.eclipse.jface.util.SafeRunnable.run(SafeRunnable.java:175)
	at org.eclipse.jface.wizard.WizardDialog.firePageChanging(WizardDialog.java:1600)
	at org.eclipse.jface.wizard.WizardDialog.doPageChanging(WizardDialog.java:929)
	at org.eclipse.jface.wizard.WizardDialog.showPage(WizardDialog.java:1218)
	at org.eclipse.jface.wizard.WizardDialog.nextPressed(WizardDialog.java:915)
	at org.eclipse.jface.wizard.WizardDialog.buttonPressed(WizardDialog.java:428)
	at org.eclipse.jface.dialogs.Dialog$2.widgetSelected(Dialog.java:624)
	at org.eclipse.swt.widgets.TypedListener.handleEvent(TypedListener.java:240)
	at org.eclipse.swt.widgets.EventTable.sendEvent(EventTable.java:84)
	at org.eclipse.swt.widgets.Widget.sendEvent(Widget.java:1258)
	at org.eclipse.swt.widgets.Display.runDeferredEvents(Display.java:3588)
	at org.eclipse.swt.widgets.Display.readAndDispatch(Display.java:3209)
	at org.eclipse.jface.window.Window.runEventLoop(Window.java:825)
	at org.eclipse.jface.window.Window.open(Window.java:801)
	at sia.ui.Start$1.widgetSelected(Start.java:114)
	at org.eclipse.swt.widgets.TypedListener.handleEvent(TypedListener.java:240)
	at org.eclipse.swt.widgets.EventTable.sendEvent(EventTable.java:84)
	at org.eclipse.swt.widgets.Widget.sendEvent(Widget.java:1258)
	at org.eclipse.swt.widgets.Display.runDeferredEvents(Display.java:3588)
	at org.eclipse.swt.widgets.Display.readAndDispatch(Display.java:3209)
	at org.eclipse.jface.window.Window.runEventLoop(Window.java:825)
	at org.eclipse.jface.window.Window.open(Window.java:801)
	at sia.ui.Start.run(Start.java:85)
	at sia.ui.SIA.guiInit(SIA.java:179)
	at sia.ui.SIA.init(SIA.java:46)
	at sia.ui.SIA.main(SIA.java:213)
Wed 19:01:11 ERROR [Thread-3] sia.ui.SIA - Retrieving contacts and conversations failed.
Traceback (most recent call last):
  File "__pyclasspath__/sia/py/fileparsers/GtalkParser.py", line 48, in getContacts
imaplib.error: [AUTHENTICATIONFAILED] Invalid credentials (Failure)

	at org.python.core.PyException.fillInStackTrace(PyException.java:70)
	at java.lang.Throwable.<init>(Throwable.java:181)
	at java.lang.Exception.<init>(Exception.java:29)
	at java.lang.RuntimeException.<init>(RuntimeException.java:32)
	at org.python.core.PyException.<init>(PyException.java:46)
	at org.python.core.PyException.doRaise(PyException.java:219)
	at org.python.core.Py.makeException(Py.java:1225)
	at org.python.core.Py.makeException(Py.java:1229)
	at org.python.core.Py.makeException(Py.java:1233)
	at sia.py.fileparsers.GtalkParser$py.getContacts$5(__pyclasspath__/sia/py/fileparsers/GtalkParser.py:143)
	at sia.py.fileparsers.GtalkParser$py.call_function(__pyclasspath__/sia/py/fileparsers/GtalkParser.py)
	at org.python.core.PyTableCode.call(PyTableCode.java:165)
	at org.python.core.PyBaseCode.call(PyBaseCode.java:301)
	at org.python.core.PyBaseCode.call(PyBaseCode.java:194)
	at org.python.core.PyFunction.__call__(PyFunction.java:387)
	at org.python.core.PyMethod.instancemethod___call__(PyMethod.java:220)
	at org.python.core.PyMethod.__call__(PyMethod.java:211)
	at org.python.core.PyMethod.__call__(PyMethod.java:201)
	at org.python.core.PyMethod.__call__(PyMethod.java:196)
	at org.python.core.PyObject._jcallexc(PyObject.java:3502)
	at org.python.proxies.sia.py.fileparsers.GtalkParser$GtalkParser$1.getContacts(Unknown Source)
	at sia.datasources.DataSource.getContacts(DataSource.java:132)
	at sia.ui.importui.ImportWizard$2.run(ImportWizard.java:295)
	at java.lang.Thread.run(Thread.java:662)
Wed 19:03:13 ERROR [Thread-3] sia.ui.SIA - Retrieving contacts and conversations failed.
Traceback (most recent call last):
  File "__pyclasspath__/sia/py/fileparsers/GtalkParser.py", line 45, in getContacts
  File "/opt/jython2.5.2/Lib/imaplib.py", line 501, in login
    raise self.error(dat[-1])
imaplib.error: [AUTHENTICATIONFAILED] Invalid credentials (Failure)

	at org.python.core.PyException.fillInStackTrace(PyException.java:70)
	at java.lang.Throwable.<init>(Throwable.java:181)
	at java.lang.Exception.<init>(Exception.java:29)
	at java.lang.RuntimeException.<init>(RuntimeException.java:32)
	at org.python.core.PyException.<init>(PyException.java:46)
	at org.python.core.PyException.doRaise(PyException.java:219)
	at org.python.core.Py.makeException(Py.java:1225)
	at org.python.core.Py.makeException(Py.java:1229)
	at org.python.core.Py.makeException(Py.java:1233)
	at imaplib$py.login$31(/opt/jython2.5.2/Lib/imaplib.py:503)
	at imaplib$py.call_function(/opt/jython2.5.2/Lib/imaplib.py)
	at org.python.core.PyTableCode.call(PyTableCode.java:165)
	at org.python.core.PyBaseCode.call(PyBaseCode.java:166)
	at org.python.core.PyFunction.__call__(PyFunction.java:338)
	at org.python.core.PyMethod.__call__(PyMethod.java:139)
	at sia.py.fileparsers.GtalkParser$py.getContacts$5(__pyclasspath__/sia/py/fileparsers/GtalkParser.py:140)
	at sia.py.fileparsers.GtalkParser$py.call_function(__pyclasspath__/sia/py/fileparsers/GtalkParser.py)
	at org.python.core.PyTableCode.call(PyTableCode.java:165)
	at org.python.core.PyBaseCode.call(PyBaseCode.java:301)
	at org.python.core.PyBaseCode.call(PyBaseCode.java:194)
	at org.python.core.PyFunction.__call__(PyFunction.java:387)
	at org.python.core.PyMethod.instancemethod___call__(PyMethod.java:220)
	at org.python.core.PyMethod.__call__(PyMethod.java:211)
	at org.python.core.PyMethod.__call__(PyMethod.java:201)
	at org.python.core.PyMethod.__call__(PyMethod.java:196)
	at org.python.core.PyObject._jcallexc(PyObject.java:3502)
	at org.python.proxies.sia.py.fileparsers.GtalkParser$GtalkParser$1.getContacts(Unknown Source)
	at sia.datasources.DataSource.getContacts(DataSource.java:132)
	at sia.ui.importui.ImportWizard$2.run(ImportWizard.java:295)
	at java.lang.Thread.run(Thread.java:662)
Wed 19:10:24 ERROR [Thread-3] sia.ui.SIA - Retrieving contacts and conversations failed.
Traceback (most recent call last):
  File "__pyclasspath__/sia/py/fileparsers/GtalkParser.py", line 45, in getContacts
  File "/opt/jython2.5.2/Lib/imaplib.py", line 501, in login
    raise self.error(dat[-1])
imaplib.error: [AUTHENTICATIONFAILED] Invalid credentials (Failure)

	at org.python.core.PyException.fillInStackTrace(PyException.java:70)
	at java.lang.Throwable.<init>(Throwable.java:181)
	at java.lang.Exception.<init>(Exception.java:29)
	at java.lang.RuntimeException.<init>(RuntimeException.java:32)
	at org.python.core.PyException.<init>(PyException.java:46)
	at org.python.core.PyException.doRaise(PyException.java:219)
	at org.python.core.Py.makeException(Py.java:1225)
	at org.python.core.Py.makeException(Py.java:1229)
	at org.python.core.Py.makeException(Py.java:1233)
	at imaplib$py.login$31(/opt/jython2.5.2/Lib/imaplib.py:503)
	at imaplib$py.call_function(/opt/jython2.5.2/Lib/imaplib.py)
	at org.python.core.PyTableCode.call(PyTableCode.java:165)
	at org.python.core.PyBaseCode.call(PyBaseCode.java:166)
	at org.python.core.PyFunction.__call__(PyFunction.java:338)
	at org.python.core.PyMethod.__call__(PyMethod.java:139)
	at sia.py.fileparsers.GtalkParser$py.getContacts$5(__pyclasspath__/sia/py/fileparsers/GtalkParser.py:136)
	at sia.py.fileparsers.GtalkParser$py.call_function(__pyclasspath__/sia/py/fileparsers/GtalkParser.py)
	at org.python.core.PyTableCode.call(PyTableCode.java:165)
	at org.python.core.PyBaseCode.call(PyBaseCode.java:301)
	at org.python.core.PyBaseCode.call(PyBaseCode.java:194)
	at org.python.core.PyFunction.__call__(PyFunction.java:387)
	at org.python.core.PyMethod.instancemethod___call__(PyMethod.java:220)
	at org.python.core.PyMethod.__call__(PyMethod.java:211)
	at org.python.core.PyMethod.__call__(PyMethod.java:201)
	at org.python.core.PyMethod.__call__(PyMethod.java:196)
	at org.python.core.PyObject._jcallexc(PyObject.java:3502)
	at org.python.proxies.sia.py.fileparsers.GtalkParser$GtalkParser$1.getContacts(Unknown Source)
	at sia.datasources.DataSource.getContacts(DataSource.java:132)
	at sia.ui.importui.ImportWizard$2.run(ImportWizard.java:295)
	at java.lang.Thread.run(Thread.java:662)
Wed 19:13:02 ERROR [Thread-3] sia.ui.SIA - Retrieving contacts and conversations failed.
Traceback (most recent call last):
  File "__pyclasspath__/sia/py/fileparsers/GtalkParser.py", line 45, in getContacts
  File "/opt/jython2.5.2/Lib/imaplib.py", line 501, in login
    raise self.error(dat[-1])
imaplib.error: [AUTHENTICATIONFAILED] Invalid credentials (Failure)

	at org.python.core.PyException.fillInStackTrace(PyException.java:70)
	at java.lang.Throwable.<init>(Throwable.java:181)
	at java.lang.Exception.<init>(Exception.java:29)
	at java.lang.RuntimeException.<init>(RuntimeException.java:32)
	at org.python.core.PyException.<init>(PyException.java:46)
	at org.python.core.PyException.doRaise(PyException.java:219)
	at org.python.core.Py.makeException(Py.java:1225)
	at org.python.core.Py.makeException(Py.java:1229)
	at org.python.core.Py.makeException(Py.java:1233)
	at imaplib$py.login$31(/opt/jython2.5.2/Lib/imaplib.py:503)
	at imaplib$py.call_function(/opt/jython2.5.2/Lib/imaplib.py)
	at org.python.core.PyTableCode.call(PyTableCode.java:165)
	at org.python.core.PyBaseCode.call(PyBaseCode.java:166)
	at org.python.core.PyFunction.__call__(PyFunction.java:338)
	at org.python.core.PyMethod.__call__(PyMethod.java:139)
	at sia.py.fileparsers.GtalkParser$py.getContacts$5(__pyclasspath__/sia/py/fileparsers/GtalkParser.py:136)
	at sia.py.fileparsers.GtalkParser$py.call_function(__pyclasspath__/sia/py/fileparsers/GtalkParser.py)
	at org.python.core.PyTableCode.call(PyTableCode.java:165)
	at org.python.core.PyBaseCode.call(PyBaseCode.java:301)
	at org.python.core.PyBaseCode.call(PyBaseCode.java:194)
	at org.python.core.PyFunction.__call__(PyFunction.java:387)
	at org.python.core.PyMethod.instancemethod___call__(PyMethod.java:220)
	at org.python.core.PyMethod.__call__(PyMethod.java:211)
	at org.python.core.PyMethod.__call__(PyMethod.java:201)
	at org.python.core.PyMethod.__call__(PyMethod.java:196)
	at org.python.core.PyObject._jcallexc(PyObject.java:3502)
	at org.python.proxies.sia.py.fileparsers.GtalkParser$GtalkParser$1.getContacts(Unknown Source)
	at sia.datasources.DataSource.getContacts(DataSource.java:132)
	at sia.ui.importui.ImportWizard$2.run(ImportWizard.java:295)
	at java.lang.Thread.run(Thread.java:662)
Wed 19:13:39 ERROR [Thread-3] sia.ui.SIA - Retrieving contacts and conversations failed.
Traceback (most recent call last):
  File "__pyclasspath__/sia/py/fileparsers/GtalkParser.py", line 45, in getContacts
  File "/opt/jython2.5.2/Lib/imaplib.py", line 501, in login
    raise self.error(dat[-1])
imaplib.error: [AUTHENTICATIONFAILED] Invalid credentials (Failure)

	at org.python.core.PyException.fillInStackTrace(PyException.java:70)
	at java.lang.Throwable.<init>(Throwable.java:181)
	at java.lang.Exception.<init>(Exception.java:29)
	at java.lang.RuntimeException.<init>(RuntimeException.java:32)
	at org.python.core.PyException.<init>(PyException.java:46)
	at org.python.core.PyException.doRaise(PyException.java:219)
	at org.python.core.Py.makeException(Py.java:1225)
	at org.python.core.Py.makeException(Py.java:1229)
	at org.python.core.Py.makeException(Py.java:1233)
	at imaplib$py.login$31(/opt/jython2.5.2/Lib/imaplib.py:503)
	at imaplib$py.call_function(/opt/jython2.5.2/Lib/imaplib.py)
	at org.python.core.PyTableCode.call(PyTableCode.java:165)
	at org.python.core.PyBaseCode.call(PyBaseCode.java:166)
	at org.python.core.PyFunction.__call__(PyFunction.java:338)
	at org.python.core.PyMethod.__call__(PyMethod.java:139)
	at sia.py.fileparsers.GtalkParser$py.getContacts$5(__pyclasspath__/sia/py/fileparsers/GtalkParser.py:136)
	at sia.py.fileparsers.GtalkParser$py.call_function(__pyclasspath__/sia/py/fileparsers/GtalkParser.py)
	at org.python.core.PyTableCode.call(PyTableCode.java:165)
	at org.python.core.PyBaseCode.call(PyBaseCode.java:301)
	at org.python.core.PyBaseCode.call(PyBaseCode.java:194)
	at org.python.core.PyFunction.__call__(PyFunction.java:387)
	at org.python.core.PyMethod.instancemethod___call__(PyMethod.java:220)
	at org.python.core.PyMethod.__call__(PyMethod.java:211)
	at org.python.core.PyMethod.__call__(PyMethod.java:201)
	at org.python.core.PyMethod.__call__(PyMethod.java:196)
	at org.python.core.PyObject._jcallexc(PyObject.java:3502)
	at org.python.proxies.sia.py.fileparsers.GtalkParser$GtalkParser$1.getContacts(Unknown Source)
	at sia.datasources.DataSource.getContacts(DataSource.java:132)
	at sia.ui.importui.ImportWizard$2.run(ImportWizard.java:295)
	at java.lang.Thread.run(Thread.java:662)
Wed 19:22:35 ERROR [Thread-3] sia.ui.SIA - Retrieving contacts and conversations failed.
Traceback (most recent call last):
  File "__pyclasspath__/sia/py/fileparsers/GtalkParser.py", line 45, in getContacts
  File "/opt/jython2.5.2/Lib/imaplib.py", line 501, in login
    raise self.error(dat[-1])
imaplib.error: [AUTHENTICATIONFAILED] Invalid credentials (Failure)

	at org.python.core.PyException.fillInStackTrace(PyException.java:70)
	at java.lang.Throwable.<init>(Throwable.java:181)
	at java.lang.Exception.<init>(Exception.java:29)
	at java.lang.RuntimeException.<init>(RuntimeException.java:32)
	at org.python.core.PyException.<init>(PyException.java:46)
	at org.python.core.PyException.doRaise(PyException.java:219)
	at org.python.core.Py.makeException(Py.java:1225)
	at org.python.core.Py.makeException(Py.java:1229)
	at org.python.core.Py.makeException(Py.java:1233)
	at imaplib$py.login$31(/opt/jython2.5.2/Lib/imaplib.py:503)
	at imaplib$py.call_function(/opt/jython2.5.2/Lib/imaplib.py)
	at org.python.core.PyTableCode.call(PyTableCode.java:165)
	at org.python.core.PyBaseCode.call(PyBaseCode.java:166)
	at org.python.core.PyFunction.__call__(PyFunction.java:338)
	at org.python.core.PyMethod.__call__(PyMethod.java:139)
	at sia.py.fileparsers.GtalkParser$py.getContacts$5(__pyclasspath__/sia/py/fileparsers/GtalkParser.py:136)
	at sia.py.fileparsers.GtalkParser$py.call_function(__pyclasspath__/sia/py/fileparsers/GtalkParser.py)
	at org.python.core.PyTableCode.call(PyTableCode.java:165)
	at org.python.core.PyBaseCode.call(PyBaseCode.java:301)
	at org.python.core.PyBaseCode.call(PyBaseCode.java:194)
	at org.python.core.PyFunction.__call__(PyFunction.java:387)
	at org.python.core.PyMethod.instancemethod___call__(PyMethod.java:220)
	at org.python.core.PyMethod.__call__(PyMethod.java:211)
	at org.python.core.PyMethod.__call__(PyMethod.java:201)
	at org.python.core.PyMethod.__call__(PyMethod.java:196)
	at org.python.core.PyObject._jcallexc(PyObject.java:3502)
	at org.python.proxies.sia.py.fileparsers.GtalkParser$GtalkParser$1.getContacts(Unknown Source)
	at sia.datasources.DataSource.getContacts(DataSource.java:132)
	at sia.ui.importui.ImportWizard$2.run(ImportWizard.java:298)
	at java.lang.Thread.run(Thread.java:662)
Wed 19:22:54 ERROR [Thread-9] sia.ui.SIA - Retrieving contacts and conversations failed.
Traceback (most recent call last):
  File "__pyclasspath__/sia/py/fileparsers/GtalkParser.py", line 47, in getContacts
  File "/opt/jython2.5.2/Lib/imaplib.py", line 621, in search
    typ, dat = self._simple_command(name, *criteria)
  File "/opt/jython2.5.2/Lib/imaplib.py", line 1055, in _simple_command
    return self._command_complete(name, self._command(name, *args))
  File "/opt/jython2.5.2/Lib/imaplib.py", line 814, in _command
    raise self.error(
imaplib.error: command SEARCH illegal in state AUTH

	at org.python.core.PyException.fillInStackTrace(PyException.java:70)
	at java.lang.Throwable.<init>(Throwable.java:181)
	at java.lang.Exception.<init>(Exception.java:29)
	at java.lang.RuntimeException.<init>(RuntimeException.java:32)
	at org.python.core.PyException.<init>(PyException.java:46)
	at org.python.core.PyException.doRaise(PyException.java:219)
	at org.python.core.Py.makeException(Py.java:1225)
	at org.python.core.Py.makeException(Py.java:1229)
	at org.python.core.Py.makeException(Py.java:1233)
	at imaplib$py._command$57(/opt/jython2.5.2/Lib/imaplib.py:879)
	at imaplib$py.call_function(/opt/jython2.5.2/Lib/imaplib.py)
	at org.python.core.PyTableCode.call(PyTableCode.java:165)
	at org.python.core.PyBaseCode.call(PyBaseCode.java:301)
	at org.python.core.PyBaseCode.call(PyBaseCode.java:194)
	at org.python.core.PyFunction.__call__(PyFunction.java:387)
	at org.python.core.PyMethod.instancemethod___call__(PyMethod.java:220)
	at org.python.core.PyMethod.__call__(PyMethod.java:211)
	at org.python.core.PyMethod.__call__(PyMethod.java:206)
	at org.python.core.PyObject._callextra(PyObject.java:527)
	at imaplib$py._simple_command$66(/opt/jython2.5.2/Lib/imaplib.py:1055)
	at imaplib$py.call_function(/opt/jython2.5.2/Lib/imaplib.py)
	at org.python.core.PyTableCode.call(PyTableCode.java:165)
	at org.python.core.PyBaseCode.call(PyBaseCode.java:301)
	at org.python.core.PyBaseCode.call(PyBaseCode.java:194)
	at org.python.core.PyFunction.__call__(PyFunction.java:387)
	at org.python.core.PyMethod.instancemethod___call__(PyMethod.java:220)
	at org.python.core.PyMethod.__call__(PyMethod.java:211)
	at org.python.core.PyMethod.__call__(PyMethod.java:206)
	at org.python.core.PyObject._callextra(PyObject.java:527)
	at imaplib$py.search$42(/opt/jython2.5.2/Lib/imaplib.py:622)
	at imaplib$py.call_function(/opt/jython2.5.2/Lib/imaplib.py)
	at org.python.core.PyTableCode.call(PyTableCode.java:165)
	at org.python.core.PyBaseCode.call(PyBaseCode.java:301)
	at org.python.core.PyBaseCode.call(PyBaseCode.java:157)
	at org.python.core.PyFunction.__call__(PyFunction.java:338)
	at org.python.core.PyMethod.__call__(PyMethod.java:139)
	at sia.py.fileparsers.GtalkParser$py.getContacts$5(__pyclasspath__/sia/py/fileparsers/GtalkParser.py:136)
	at sia.py.fileparsers.GtalkParser$py.call_function(__pyclasspath__/sia/py/fileparsers/GtalkParser.py)
	at org.python.core.PyTableCode.call(PyTableCode.java:165)
	at org.python.core.PyBaseCode.call(PyBaseCode.java:301)
	at org.python.core.PyBaseCode.call(PyBaseCode.java:194)
	at org.python.core.PyFunction.__call__(PyFunction.java:387)
	at org.python.core.PyMethod.instancemethod___call__(PyMethod.java:220)
	at org.python.core.PyMethod.__call__(PyMethod.java:211)
	at org.python.core.PyMethod.__call__(PyMethod.java:201)
	at org.python.core.PyMethod.__call__(PyMethod.java:196)
	at org.python.core.PyObject._jcallexc(PyObject.java:3502)
	at org.python.proxies.sia.py.fileparsers.GtalkParser$GtalkParser$1.getContacts(Unknown Source)
	at sia.datasources.DataSource.getContacts(DataSource.java:132)
	at sia.ui.importui.ImportWizard$2.run(ImportWizard.java:298)
	at java.lang.Thread.run(Thread.java:662)
Wed 19:31:13 ERROR [Thread-3] sia.ui.SIA - Retrieving contacts and conversations failed.
Traceback (most recent call last):
  File "__pyclasspath__/sia/py/fileparsers/GtalkParser.py", line 57, in getContacts
ValueError

	at org.python.core.PyException.fillInStackTrace(PyException.java:70)
	at java.lang.Throwable.<init>(Throwable.java:181)
	at java.lang.Exception.<init>(Exception.java:29)
	at java.lang.RuntimeException.<init>(RuntimeException.java:32)
	at org.python.core.PyException.<init>(PyException.java:46)
	at org.python.core.PyException.doRaise(PyException.java:219)
	at org.python.core.Py.makeException(Py.java:1225)
	at org.python.core.Py.makeException(Py.java:1229)
	at org.python.core.Py.makeException(Py.java:1233)
	at sia.py.fileparsers.GtalkParser$py.getContacts$5(__pyclasspath__/sia/py/fileparsers/GtalkParser.py:146)
	at sia.py.fileparsers.GtalkParser$py.call_function(__pyclasspath__/sia/py/fileparsers/GtalkParser.py)
	at org.python.core.PyTableCode.call(PyTableCode.java:165)
	at org.python.core.PyBaseCode.call(PyBaseCode.java:301)
	at org.python.core.PyBaseCode.call(PyBaseCode.java:194)
	at org.python.core.PyFunction.__call__(PyFunction.java:387)
	at org.python.core.PyMethod.instancemethod___call__(PyMethod.java:220)
	at org.python.core.PyMethod.__call__(PyMethod.java:211)
	at org.python.core.PyMethod.__call__(PyMethod.java:201)
	at org.python.core.PyMethod.__call__(PyMethod.java:196)
	at org.python.core.PyObject._jcallexc(PyObject.java:3502)
	at org.python.proxies.sia.py.fileparsers.GtalkParser$GtalkParser$1.getContacts(Unknown Source)
	at sia.datasources.DataSource.getContacts(DataSource.java:132)
	at sia.ui.importui.ImportWizard$2.run(ImportWizard.java:298)
	at java.lang.Thread.run(Thread.java:662)
Wed 19:31:23 ERROR [Thread-9] sia.ui.SIA - Retrieving contacts and conversations failed.
Traceback (most recent call last):
  File "__pyclasspath__/sia/py/fileparsers/GtalkParser.py", line 50, in getContacts
ValueError

	at org.python.core.PyException.fillInStackTrace(PyException.java:70)
	at java.lang.Throwable.<init>(Throwable.java:181)
	at java.lang.Exception.<init>(Exception.java:29)
	at java.lang.RuntimeException.<init>(RuntimeException.java:32)
	at org.python.core.PyException.<init>(PyException.java:46)
	at org.python.core.PyException.doRaise(PyException.java:219)
	at org.python.core.Py.makeException(Py.java:1225)
	at org.python.core.Py.makeException(Py.java:1229)
	at org.python.core.Py.makeException(Py.java:1233)
	at sia.py.fileparsers.GtalkParser$py.getContacts$5(__pyclasspath__/sia/py/fileparsers/GtalkParser.py:146)
	at sia.py.fileparsers.GtalkParser$py.call_function(__pyclasspath__/sia/py/fileparsers/GtalkParser.py)
	at org.python.core.PyTableCode.call(PyTableCode.java:165)
	at org.python.core.PyBaseCode.call(PyBaseCode.java:301)
	at org.python.core.PyBaseCode.call(PyBaseCode.java:194)
	at org.python.core.PyFunction.__call__(PyFunction.java:387)
	at org.python.core.PyMethod.instancemethod___call__(PyMethod.java:220)
	at org.python.core.PyMethod.__call__(PyMethod.java:211)
	at org.python.core.PyMethod.__call__(PyMethod.java:201)
	at org.python.core.PyMethod.__call__(PyMethod.java:196)
	at org.python.core.PyObject._jcallexc(PyObject.java:3502)
	at org.python.proxies.sia.py.fileparsers.GtalkParser$GtalkParser$1.getContacts(Unknown Source)
	at sia.datasources.DataSource.getContacts(DataSource.java:132)
	at sia.ui.importui.ImportWizard$2.run(ImportWizard.java:298)
	at java.lang.Thread.run(Thread.java:662)
Wed 19:42:23 ERROR [Thread-9] sia.ui.SIA - Retrieving contacts and conversations failed.
Traceback (most recent call last):
  File "__pyclasspath__/sia/py/fileparsers/GtalkParser.py", line 50, in getContacts
ValueError

	at org.python.core.PyException.fillInStackTrace(PyException.java:70)
	at java.lang.Throwable.<init>(Throwable.java:181)
	at java.lang.Exception.<init>(Exception.java:29)
	at java.lang.RuntimeException.<init>(RuntimeException.java:32)
	at org.python.core.PyException.<init>(PyException.java:46)
	at org.python.core.PyException.doRaise(PyException.java:219)
	at org.python.core.Py.makeException(Py.java:1225)
	at org.python.core.Py.makeException(Py.java:1229)
	at org.python.core.Py.makeException(Py.java:1233)
	at sia.py.fileparsers.GtalkParser$py.getContacts$5(__pyclasspath__/sia/py/fileparsers/GtalkParser.py:148)
	at sia.py.fileparsers.GtalkParser$py.call_function(__pyclasspath__/sia/py/fileparsers/GtalkParser.py)
	at org.python.core.PyTableCode.call(PyTableCode.java:165)
	at org.python.core.PyBaseCode.call(PyBaseCode.java:301)
	at org.python.core.PyBaseCode.call(PyBaseCode.java:194)
	at org.python.core.PyFunction.__call__(PyFunction.java:387)
	at org.python.core.PyMethod.instancemethod___call__(PyMethod.java:220)
	at org.python.core.PyMethod.__call__(PyMethod.java:211)
	at org.python.core.PyMethod.__call__(PyMethod.java:201)
	at org.python.core.PyMethod.__call__(PyMethod.java:196)
	at org.python.core.PyObject._jcallexc(PyObject.java:3502)
	at org.python.proxies.sia.py.fileparsers.GtalkParser$GtalkParser$1.getContacts(Unknown Source)
	at sia.datasources.DataSource.getContacts(DataSource.java:134)
	at sia.ui.importui.ImportWizard$2.run(ImportWizard.java:307)
	at java.lang.Thread.run(Thread.java:662)
Wed 21:55:07 ERROR [Thread-5] sia.ui.SIA - Unexpected error on saving data into database.
org.sormula.operation.OperationException: execute() error
	at org.sormula.operation.ModifyOperation.execute(ModifyOperation.java:161)
	at org.sormula.operation.ModifyOperation.modify(ModifyOperation.java:201)
	at org.sormula.operation.InsertOperation.insert(InsertOperation.java:84)
	at org.sormula.Table.insert(Table.java:523)
	at sia.datasources.DataSource.save(DataSource.java:195)
	at sia.ui.importui.ImportWizard$3.run(ImportWizard.java:339)
	at java.lang.Thread.run(Thread.java:662)
Caused by: java.sql.SQLException: contactaccount.id may not be NULL
	at org.sqlite.DB.execute(DB.java:275)
	at org.sqlite.DB.executeUpdate(DB.java:281)
	at org.sqlite.PrepStmt.executeUpdate(PrepStmt.java:77)
	at org.sormula.operation.ModifyOperation.execute(ModifyOperation.java:144)
	... 6 more
Wed 21:57:20 ERROR [Thread-11] sia.ui.SIA - Unexpected error on saving data into database.
org.sormula.operation.OperationException: execute() error
	at org.sormula.operation.ModifyOperation.execute(ModifyOperation.java:161)
	at org.sormula.operation.ModifyOperation.modify(ModifyOperation.java:201)
	at org.sormula.operation.InsertOperation.insert(InsertOperation.java:84)
	at org.sormula.Table.insert(Table.java:523)
	at sia.datasources.DataSource.save(DataSource.java:195)
	at sia.ui.importui.ImportWizard$3.run(ImportWizard.java:339)
	at java.lang.Thread.run(Thread.java:662)
Caused by: java.sql.SQLException: contactaccount.id may not be NULL
	at org.sqlite.DB.execute(DB.java:275)
	at org.sqlite.DB.executeUpdate(DB.java:281)
	at org.sqlite.PrepStmt.executeUpdate(PrepStmt.java:77)
	at org.sormula.operation.ModifyOperation.execute(ModifyOperation.java:144)
	... 6 more
Wed 21:58:20 ERROR [Thread-5] sia.ui.SIA - Unexpected error on saving data into database.
org.sormula.operation.OperationException: execute() error
	at org.sormula.operation.ModifyOperation.execute(ModifyOperation.java:161)
	at org.sormula.operation.ModifyOperation.modify(ModifyOperation.java:201)
	at org.sormula.operation.InsertOperation.insert(InsertOperation.java:84)
	at org.sormula.Table.insert(Table.java:523)
	at sia.datasources.DataSource.save(DataSource.java:195)
	at sia.ui.importui.ImportWizard$3.run(ImportWizard.java:339)
	at java.lang.Thread.run(Thread.java:662)
Caused by: java.sql.SQLException: contactaccount.id may not be NULL
	at org.sqlite.DB.execute(DB.java:275)
	at org.sqlite.DB.executeUpdate(DB.java:281)
	at org.sqlite.PrepStmt.executeUpdate(PrepStmt.java:77)
	at org.sormula.operation.ModifyOperation.execute(ModifyOperation.java:144)
	... 6 more
